Workbook

Sheet README
A1: CS Pulse — FDE Discovery Workbook
A3: Purpose | B3: Capture per-persona discovery data so we can configure the customer's tenant: KPI selections, pillar weights, signal channels, stakeholders, success outcomes, and decision cadence.
A4: How to use | B4: FDE sends the relevant tab to each persona's stakeholder. Stakeholder fills blue cells. FDE reviews, then the Consolidation tab rolls everything into a config-export view that maps directly to CustomerConfig fields.
A5: Color legend — blue | B5: Input cell. The stakeholder fills this in.
A6: Color legend — yellow | B6: Required input. Do not skip.
A7: Color legend — black | B7: Formula. Do not edit.
A8: Color legend — green | B8: Cross-sheet link on Consolidation. Pulls from persona tabs.
A9: Color legend — red | B9: Conflict flag. Two personas disagree by more than the tolerance band.
A10: Tabs | B10: README · CRO · CFO · CEO · VPCS · CSM · Consolidation
A11: Persona owner mapping | B11: CRO = revenue. CFO = ROI / proof. CEO = portfolio rollup. VP CS = team + playbooks. CSM = daily account work.
A12: Pillar legend | B12: P1 Deployment Velocity · P2 Operational Stability · P3 Workload Performance · P4 Channel & Partner Health · P5 Expansion Readiness. (Names vary by vertical — defaults shown are DC2_S.)
A13: KPI tier | B13: Default = Predictive 11 (11 KPIs across the 5 pillars). Pick Starter 9 for early-stage customers, or Full 43 for mature data programs.
A14: Default rule | B14: If a stakeholder cannot answer, use the platform default and flag it in the Notes column. Do not invent.
A15: Sign-off | B15: When all 5 tabs are filled and Consolidation has no red flags, the engagement lead countersigns and onboarding moves to the 4-CSV upload.
A17: Version 1.0 · May 2026 · Internal — NDA covered

Sheet CRO
A1: CRO — Chief Revenue Officer
A2: Owner of forward revenue. Cares about: NRR forecast, revenue at risk, expansion pipeline, account-level explainability.
A4: A. Stakeholder identity
A5: Field | B5: Answer (your input) | C5: Notes | D5: Default / hint | E5: Required? | F5: Source / system
A6: Full name | E6: Y
A7: Title | D7: CRO | E7: Y
A8: Email | E8: Y
A9: Time zone | D9: PT / ET / CET / IST | E9: Y
A10: Years in role | D10: 0-30 | E10: N
A11: Reports to | E11: N
A13: B. Top 5 pain points (rank 1=worst, 5=mildly annoying)
A14: Rank | B14: Pain point | C14: Frequency (daily/weekly/monthly) | D14: Cost if unsolved | E14: Severity (1-5) | F14: Owner today
A15: 1
A16: 2
A17: 3
A18: 4
A19: 5
A21: C. Current KPIs you track today
A22: KPI name | B22: Source system | C22: Frequency | D22: Owner | E22: Is this in CS Pulse today? (Y/N) | F22: Notes
A23: NRR (gross / net)
A24: Logo retention
A25: Pipeline coverage on renewals
A26: Expansion bookings
A27: At-risk ARR
A28: Churn $
A29: Time to first value
A32: D. Pillar weight allocation (your view) — must sum to 100%
A33: Pillar | B33: Your weight % | C33: Platform default % | D33: Delta | E33: Justification
A34: P1 Deployment Velocity | C34: 0.15 | D34: =IFERROR(B34-C34,0) -> -0.15
A35: P2 Operational Stability | C35: 0.2 | D35: =IFERROR(B35-C35,0) -> -0.2
A36: P3 Workload Performance | C36: 0.25 | D36: =IFERROR(B36-C36,0) -> -0.25
A37: P4 Channel & Partner Health | C37: 0.15 | D37: =IFERROR(B37-C37,0) -> -0.15
A38: P5 Expansion Readiness | C38: 0.25 | D38: =IFERROR(B38-C38,0) -> -0.25
A39: Sum (must = 100%) | B39: =SUM(B34:B38) -> 0 | D39: =IF(ABS(B39-1)<0.001,"OK","Adjust — must total 100%") -> Adjust — must total 100%
A41: E. Signal sources (where does the customer hear about risk / expansion today?)
A42: Channel type | B42: Identifier (channel / alias / tool) | C42: Frequency | D42: Who monitors it? | E42: Wire to CS Pulse? (Y/N) | F42: Notes
A43: Slack channel(s) | F43: e.g. #cs-acme
A44: Shared email alias | F44: e.g. cs-team@...
A45: Call transcript tool | F45: Gong / Chorus / Zoom
A46: CRM events | F46: Salesforce / HubSpot
...

Sheet CFO
A1: CFO — Chief Financial Officer
A2: Owner of ROI proof. Cares about: every dollar of CS investment is justified, attribution is traceable, audit trail is defensible.
A4: A. Stakeholder identity
A5: Field | B5: Answer (your input) | C5: Notes | D5: Default / hint | E5: Required? | F5: Source / system
A6: Full name | E6: Y
A7: Title | D7: CFO | E7: Y
A8: Email | E8: Y
A9: Time zone | D9: PT / ET / CET / IST | E9: Y
A10: Years in role | D10: 0-30 | E10: N
A11: Reports to | E11: N
A13: B. Top 5 pain points (rank 1=worst, 5=mildly annoying)
A14: Rank | B14: Pain point | C14: Frequency (daily/weekly/monthly) | D14: Cost if unsolved | E14: Severity (1-5) | F14: Owner today
A15: 1
A16: 2
A17: 3
A18: 4
A19: 5
A21: C. Current KPIs you track today
A22: KPI name | B22: Source system | C22: Frequency | D22: Owner | E22: Is this in CS Pulse today? (Y/N) | F22: Notes
A23: CS cost as % of ARR
A24: Revenue Protected $
A25: Realized ROI x
A26: CAC payback
A27: Gross margin on CS-touched accounts
A28: CS budget vs. plan
A32: D. Pillar weight allocation (your view) — must sum to 100%
A33: Pillar | B33: Your weight % | C33: Platform default % | D33: Delta | E33: Justification
A34: P1 Deployment Velocity | C34: 0.2 | D34: =IFERROR(B34-C34,0) -> -0.2
A35: P2 Operational Stability | C35: 0.25 | D35: =IFERROR(B35-C35,0) -> -0.25
A36: P3 Workload Performance | C36: 0.2 | D36: =IFERROR(B36-C36,0) -> -0.2
A37: P4 Channel & Partner Health | C37: 0.15 | D37: =IFERROR(B37-C37,0) -> -0.15
A38: P5 Expansion Readiness | C38: 0.2 | D38: =IFERROR(B38-C38,0) -> -0.2
A39: Sum (must = 100%) | B39: =SUM(B34:B38) -> 0 | D39: =IF(ABS(B39-1)<0.001,"OK","Adjust — must total 100%") -> Adjust — must total 100%
A41: E. Signal sources (where does the customer hear about risk / expansion today?)
A42: Channel type | B42: Identifier (channel / alias / tool) | C42: Frequency | D42: Who monitors it? | E42: Wire to CS Pulse? (Y/N) | F42: Notes
A43: Slack channel(s) | F43: e.g. #cs-acme
A44: Shared email alias | F44: e.g. cs-team@...
A45: Call transcript tool | F45: Gong / Chorus / Zoom
A46: CRM events | F46: Salesforce / HubSpot
A47: Support tickets | F47: Zendesk / ServiceNow
...

Sheet CEO
A1: CEO — Chief Executive Officer
A2: Owner of the portfolio rollup. Cares about: one screen, every portfolio company, board-ready summary numbers.
A4: A. Stakeholder identity
A5: Field | B5: Answer (your input) | C5: Notes | D5: Default / hint | E5: Required? | F5: Source / system
A6: Full name | E6: Y
A7: Title | D7: CEO | E7: Y
A8: Email | E8: Y
A9: Time zone | D9: PT / ET / CET / IST | E9: Y
A10: Years in role | D10: 0-30 | E10: N
A11: Reports to | E11: N
A13: B. Top 5 pain points (rank 1=worst, 5=mildly annoying)
A14: Rank | B14: Pain point | C14: Frequency (daily/weekly/monthly) | D14: Cost if unsolved | E14: Severity (1-5) | F14: Owner today
A15: 1
A16: 2
A17: 3
A18: 4
A19: 5
A21: C. Current KPIs you track today
A22: KPI name | B22: Source system | C22: Frequency | D22: Owner | E22: Is this in CS Pulse today? (Y/N) | F22: Notes
A23: Portfolio-weighted NRR
A24: Top 5 at-risk accounts $
A25: ARR by segment
A26: Growth rate
A27: Customer concentration
A28: Board-ready exec summary
A29: Per-BU CS investment
A32: D. Pillar weight allocation (your view) — must sum to 100%
A33: Pillar | B33: Your weight % | C33: Platform default % | D33: Delta | E33: Justification
A34: P1 Deployment Velocity | C34: 0.15 | D34: =IFERROR(B34-C34,0) -> -0.15
A35: P2 Operational Stability | C35: 0.2 | D35: =IFERROR(B35-C35,0) -> -0.2
A36: P3 Workload Performance | C36: 0.2 | D36: =IFERROR(B36-C36,0) -> -0.2
A37: P4 Channel & Partner Health | C37: 0.2 | D37: =IFERROR(B37-C37,0) -> -0.2
A38: P5 Expansion Readiness | C38: 0.25 | D38: =IFERROR(B38-C38,0) -> -0.25
A39: Sum (must = 100%) | B39: =SUM(B34:B38) -> 0 | D39: =IF(ABS(B39-1)<0.001,"OK","Adjust — must total 100%") -> Adjust — must total 100%
A41: E. Signal sources (where does the customer hear about risk / expansion today?)
A42: Channel type | B42: Identifier (channel / alias / tool) | C42: Frequency | D42: Who monitors it? | E42: Wire to CS Pulse? (Y/N) | F42: Notes
A43: Slack channel(s) | F43: e.g. #cs-acme
A44: Shared email alias | F44: e.g. cs-team@...
A45: Call transcript tool | F45: Gong / Chorus / Zoom
A46: CRM events | F46: Salesforce / HubSpot
...

Sheet VPCS
A1: VP CS — VP of Customer Success
A2: Owner of the CS function. Cares about: team capacity, CSM performance, playbook execution rate, weekly business review readiness.
A4: A. Stakeholder identity
A5: Field | B5: Answer (your input) | C5: Notes | D5: Default / hint | E5: Required? | F5: Source / system
A6: Full name | E6: Y
A7: Title | D7: VP CS | E7: Y
A8: Email | E8: Y
A9: Time zone | D9: PT / ET / CET / IST | E9: Y
A10: Years in role | D10: 0-30 | E10: N
A11: Reports to | E11: N
A13: B. Top 5 pain points (rank 1=worst, 5=mildly annoying)
A14: Rank | B14: Pain point | C14: Frequency (daily/weekly/monthly) | D14: Cost if unsolved | E14: Severity (1-5) | F14: Owner today
A15: 1
A16: 2
A17: 3
A18: 4
A19: 5
A21: C. Current KPIs you track today
A22: KPI name | B22: Source system | C22: Frequency | D22: Owner | E22: Is this in CS Pulse today? (Y/N) | F22: Notes
A23: Accounts per CSM
A24: Playbook execution rate %
A25: Playbook success rate %
A26: QBR completion rate
A27: CSM-to-revenue ratio
A28: Average response time to risk signal
A29: Team capacity index
A32: D. Pillar weight allocation (your view) — must sum to 100%
A33: Pillar | B33: Your weight % | C33: Platform default % | D33: Delta | E33: Justification
A34: P1 Deployment Velocity | C34: 0.2 | D34: =IFERROR(B34-C34,0) -> -0.2
A35: P2 Operational Stability | C35: 0.2 | D35: =IFERROR(B35-C35,0) -> -0.2
A36: P3 Workload Performance | C36: 0.2 | D36: =IFERROR(B36-C36,0) -> -0.2
A37: P4 Channel & Partner Health | C37: 0.2 | D37: =IFERROR(B37-C37,0) -> -0.2
A38: P5 Expansion Readiness | C38: 0.2 | D38: =IFERROR(B38-C38,0) -> -0.2
A39: Sum (must = 100%) | B39: =SUM(B34:B38) -> 0 | D39: =IF(ABS(B39-1)<0.001,"OK","Adjust — must total 100%") -> Adjust — must total 100%
A41: E. Signal sources (where does the customer hear about risk / expansion today?)
A42: Channel type | B42: Identifier (channel / alias / tool) | C42: Frequency | D42: Who monitors it? | E42: Wire to CS Pulse? (Y/N) | F42: Notes
A43: Slack channel(s) | F43: e.g. #cs-acme
A44: Shared email alias | F44: e.g. cs-team@...
A45: Call transcript tool | F45: Gong / Chorus / Zoom
A46: CRM events | F46: Salesforce / HubSpot
...

Sheet CSM
A1: CSM — Customer Success Manager
A2: Owner of the daily account work. Cares about: today's Kanban, what to do next, signal triage, time-to-next-action.
A4: A. Stakeholder identity
A5: Field | B5: Answer (your input) | C5: Notes | D5: Default / hint | E5: Required? | F5: Source / system
A6: Full name | E6: Y
A7: Title | D7: CSM | E7: Y
A8: Email | E8: Y
A9: Time zone | D9: PT / ET / CET / IST | E9: Y
A10: Years in role | D10: 0-30 | E10: N
A11: Reports to | E11: N
A13: B. Top 5 pain points (rank 1=worst, 5=mildly annoying)
A14: Rank | B14: Pain point | C14: Frequency (daily/weekly/monthly) | D14: Cost if unsolved | E14: Severity (1-5) | F14: Owner today
A15: 1
A16: 2
A17: 3
A18: 4
A19: 5
A21: C. Current KPIs you track today
A22: KPI name | B22: Source system | C22: Frequency | D22: Owner | E22: Is this in CS Pulse today? (Y/N) | F22: Notes
A23: Accounts with overdue follow-up
A24: Open playbook count
A25: Win rate on assigned playbooks
A26: Avg time to first response on risk signal
A27: QBR completion this quarter
A28: NPS / sentiment for owned accounts
A32: D. Pillar weight allocation (your view) — must sum to 100%
A33: Pillar | B33: Your weight % | C33: Platform default % | D33: Delta | E33: Justification
A34: P1 Deployment Velocity | C34: 0.2 | D34: =IFERROR(B34-C34,0) -> -0.2
A35: P2 Operational Stability | C35: 0.25 | D35: =IFERROR(B35-C35,0) -> -0.25
A36: P3 Workload Performance | C36: 0.2 | D36: =IFERROR(B36-C36,0) -> -0.2
A37: P4 Channel & Partner Health | C37: 0.15 | D37: =IFERROR(B37-C37,0) -> -0.15
A38: P5 Expansion Readiness | C38: 0.2 | D38: =IFERROR(B38-C38,0) -> -0.2
A39: Sum (must = 100%) | B39: =SUM(B34:B38) -> 0 | D39: =IF(ABS(B39-1)<0.001,"OK","Adjust — must total 100%") -> Adjust — must total 100%
A41: E. Signal sources (where does the customer hear about risk / expansion today?)
A42: Channel type | B42: Identifier (channel / alias / tool) | C42: Frequency | D42: Who monitors it? | E42: Wire to CS Pulse? (Y/N) | F42: Notes
A43: Slack channel(s) | F43: e.g. #cs-acme
A44: Shared email alias | F44: e.g. cs-team@...
A45: Call transcript tool | F45: Gong / Chorus / Zoom
A46: CRM events | F46: Salesforce / HubSpot
A47: Support tickets | F47: Zendesk / ServiceNow
...

Sheet Consolidation
A1: Consolidation — cross-persona rollup + CustomerConfig export
A2: Green cells pull live from persona tabs. Black cells are formulas. Red flags = conflict beyond tolerance.
A4: 1. Pillar weight comparison (per-persona)
A5: Pillar | B5: CRO | C5: CFO | D5: CEO | E5: VPCS | F5: CSM | G5: Mean (recommended) | H5: Range (max - min)
A6: P1 Deployment Velocity | B6: =CRO!B34 -> 0 | C6: =CFO!B34 -> 0 | D6: =CEO!B34 -> 0 | E6: =VPCS!B34 -> 0 | F6: =CSM!B34 -> 0 | G6: =IFERROR(AVERAGE(B6:F6),0) -> 0 | H6: =IFERROR(MAX(B6:F6)-MIN(B6:F6),0) -> 0
A7: P2 Operational Stability | B7: =CRO!B35 -> 0 | C7: =CFO!B35 -> 0 | D7: =CEO!B35 -> 0 | E7: =VPCS!B35 -> 0 | F7: =CSM!B35 -> 0 | G7: =IFERROR(AVERAGE(B7:F7),0) -> 0 | H7: =IFERROR(MAX(B7:F7)-MIN(B7:F7),0) -> 0
A8: P3 Workload Performance | B8: =CRO!B36 -> 0 | C8: =CFO!B36 -> 0 | D8: =CEO!B36 -> 0 | E8: =VPCS!B36 -> 0 | F8: =CSM!B36 -> 0 | G8: =IFERROR(AVERAGE(B8:F8),0) -> 0 | H8: =IFERROR(MAX(B8:F8)-MIN(B8:F8),0) -> 0
A9: P4 Channel & Partner Health | B9: =CRO!B37 -> 0 | C9: =CFO!B37 -> 0 | D9: =CEO!B37 -> 0 | E9: =VPCS!B37 -> 0 | F9: =CSM!B37 -> 0 | G9: =IFERROR(AVERAGE(B9:F9),0) -> 0 | H9: =IFERROR(MAX(B9:F9)-MIN(B9:F9),0) -> 0
A10: P5 Expansion Readiness | B10: =CRO!B38 -> 0 | C10: =CFO!B38 -> 0 | D10: =CEO!B38 -> 0 | E10: =VPCS!B38 -> 0 | F10: =CSM!B38 -> 0 | G10: =IFERROR(AVERAGE(B10:F10),0) -> 0 | H10: =IFERROR(MAX(B10:F10)-MIN(B10:F10),0) -> 0
A11: Sum check (each column should = 100%) | B11: =SUM(B6:B10) -> 0 | C11: =SUM(C6:C10) -> 0 | D11: =SUM(D6:D10) -> 0 | E11: =SUM(E6:E10) -> 0 | F11: =SUM(F6:F10) -> 0
A13: 2. Conflict flags (range > 10pp on any pillar = red)
A14: Pillar | B14: Range | C14: Status | D14: Action
A15: P1 Deployment Velocity | B15: =H6 -> 0 | C15: =IF(B15>0.1,"CONFLICT","OK") -> OK | D15: =IF(B15>0.1,"FDE to drive consensus before onboarding","No action — within tolerance") -> No action — within tolerance
A16: P2 Operational Stability | B16: =H7 -> 0 | C16: =IF(B16>0.1,"CONFLICT","OK") -> OK | D16: =IF(B16>0.1,"FDE to drive consensus before onboarding","No action — within tolerance") -> No action — within tolerance
A17: P3 Workload Performance | B17: =H8 -> 0 | C17: =IF(B17>0.1,"CONFLICT","OK") -> OK | D17: =IF(B17>0.1,"FDE to drive consensus before onboarding","No action — within tolerance") -> No action — within tolerance
A18: P4 Channel & Partner Health | B18: =H9 -> 0 | C18: =IF(B18>0.1,"CONFLICT","OK") -> OK | D18: =IF(B18>0.1,"FDE to drive consensus before onboarding","No action — within tolerance") -> No action — within tolerance
A19: P5 Expansion Readiness | B19: =H10 -> 0 | C19: =IF(B19>0.1,"CONFLICT","OK") -> OK | D19: =IF(B19>0.1,"FDE to drive consensus before onboarding","No action — within tolerance") -> No action — within tolerance
A21: 3. Persona-eval scoreboard
A22: Persona | B22: Score (0-20) | C22: Threshold | D22: Pass? | E22: Gap to fix first
A23: CRO | B23: =IFERROR(CRO!C62,0) -> 0 | C23: 16 | D23: =IF(B23>=C23,"PASS","BELOW") -> BELOW
A24: CFO | B24: =IFERROR(CFO!C62,0) -> 0 | C24: 16 | D24: =IF(B24>=C24,"PASS","BELOW") -> BELOW
A25: CEO | B25: =IFERROR(CEO!C62,0) -> 0 | C25: 16 | D25: =IF(B25>=C25,"PASS","BELOW") -> BELOW
A26: VPCS | B26: =IFERROR(VPCS!C62,0) -> 0 | C26: 16 | D26: =IF(B26>=C26,"PASS","BELOW") -> BELOW
A27: CSM | B27: =IFERROR(CSM!C62,0) -> 0 | C27: 16 | D27: =IF(B27>=C27,"PASS","BELOW") -> BELOW
A28: Portfolio total | B28: =SUM(B23:B27) -> 0 | C28: 80 | D28: =IF(B28>=80,"READY FOR HANDOVER","NEEDS MORE CALIBRATION") -> NEEDS MORE CALIBRATION
A30: 4. CustomerConfig export — paste-ready for create_customer / configure_customer_kpis
A31: CustomerConfig field | B31: Value to write | C31: Source | D31: Notes
A32: dc2s_pillar_weights.P1 | B32: =G6 -> 0 | C32: Mean of 5 personas (section 1) | D32: JSON key P1
A33: dc2s_pillar_weights.P2 | B33: =G7 -> 0 | C33: Mean of 5 personas (section 1) | D33: JSON key P2
A34: dc2s_pillar_weights.P3 | B34: =G8 -> 0 | C34: Mean of 5 personas (section 1) | D34: JSON key P3
A35: dc2s_pillar_weights.P4 | B35: =G9 -> 0 | C35: Mean of 5 personas (section 1) | D35: JSON key P4
A36: dc2s_pillar_weights.P5 | B36: =G10 -> 0 | C36: Mean of 5 personas (section 1) | D36: JSON key P5
A37: kpi_tier | B37: Predictive 11 | C37: Default | D37: Override to Starter 9 or Full 43 if customer asks
A38: vertical | B38: DC2_S | C38: Default | D38: Set per engagement
A39: signal_channels | B39: See section 5 | C39: Per-persona signal sources rolled up | D39: Free-form list, deduped
A40: playbook_overlays | B40: See engagement-specific overlay folder | C40: FDE authored | D40: verticals/customer{N}/config/playbook_overlays.json
A42: 5. Signal channels rolled up — wire into signal_channels.json
A43: Channel type | B43: CRO | C43: CFO | D43: CEO | E43: VPCS | F43: CSM | G43: Wire? (Y/N) | H43: FDE notes
A44: Slack channel(s)
A45: Shared email alias
...
